<?xml version="1.0" encoding="utf-8"?>
<robot name="Custom_Upper_Body">


	  <material name="blue">
	    	<color rgba="0 0 0.8 1"/>
	  </material>
	  <material name="black">
	    	<color rgba="0 0 0 1"/>
	  </material>
	  <material name="white">
	    	<color rgba="1 1 1 1"/>
	  </material>
  	<material name="red">
    		<color rgba="0.8 0 0 1"/>
  	</material>
  	<material name="green">
    		<color rgba="0 0.8 0 1"/>
  	</material>
  	
  	
	<link name="base">
		<mass value="0.3"/>
		<inertial>
			<origin xyz="0 0 0" rpy="0 0 0"></origin>
			<mass value="0.3"></mass>
			<inertia ixx="0.000444379589701896" ixy="0" ixz="0" iyy="0.00048561348802354" iyz="0" izz="0.000421911604661064"></inertia>
		</inertial>
		<visual>
			<origin xyz="0 0 0" rpy="0 0 0"></origin>
			<geometry>
				<box size="0.3 0.15 0.4"/>
			</geometry>
			<material name="white"/>
		</visual>
		<collision>
			<origin xyz="0 0 0" rpy="0 0 0"></origin>
			<geometry>
				<box size="0.3 0.15 0.4"/>
			</geometry>
		</collision>
	</link>
	
	<joint name="base_to_r_shoulder_yaw" type="revolute">
	    <parent link="base"/>
	    <child link="r_shoulder_yaw"/>
	    <origin xyz="0.16 0. 0.15" rpy="0 0 0"/>
	    <axis xyz="0 0 1"></axis>
	    <limit effort="3.1" lower="-1.57" upper="1.57" velocity="7.0"></limit>
  	</joint>
	
	<link name="r_shoulder_yaw">
		<inertial>
			<origin xyz="0 0 0" rpy="0 0 0"></origin>
			<mass value="0.1"></mass>
			<inertia ixx="0.000444379589701896" ixy="0" ixz="0" iyy="0.00048561348802354" iyz="0" izz="0.000421911604661064"></inertia>
		</inertial>
		<visual>
			<origin xyz="0 0 0" rpy="0 0 0"></origin>
			<geometry>
				<cylinder length="0.1" radius="0.01"/>
			</geometry>
			<material name="blue"/>
		</visual>
		<collision>
			<origin xyz="0 0 0" rpy="0 0 0"></origin>
			<geometry>
				<cylinder length="0.1" radius="0.01"/>
			</geometry>
		</collision>
	</link>
	
	<joint name="r_shoulder_yaw_to_shoulder_roll" type="revolute">
	    <parent link="r_shoulder_yaw"/>
	    <child link="r_shoulder_roll"/>
	    <origin xyz="0.018 0 0" rpy="0 1.57 0"/>
	    <axis xyz="0 0 1"></axis>
	    <limit effort="3.1" lower="-1.57" upper="1.57" velocity="7.0"></limit>
  	</joint>
	
	<link name="r_shoulder_roll">
		<inertial>
			<origin xyz="0 0 0" rpy="0 0 0"></origin>
			<mass value="0.1"></mass>
			<inertia ixx="0.000444379589701896" ixy="0" ixz="0" iyy="0.00048561348802354" iyz="0" izz="0.000421911604661064"></inertia>
		</inertial>
		<visual>
			<origin xyz="0 0 0" rpy="0 0 0"></origin>
			<geometry>
				<cylinder length="0.01" radius="0.05"/>
			</geometry>
			<material name="black"/>
		</visual>
		<collision>
			<origin xyz="0 0 0" rpy="0 0 0"></origin>
			<geometry>
				<cylinder length="0.01" radius="0.05"/>
			</geometry>
		</collision>
	</link>
	
	<joint name="r_shoulder_roll_to_shoulder_pitch" type="revolute">
	    <parent link="r_shoulder_roll"/>
	    <child link="r_shoulder_pitch"/>
	    <origin xyz="0 0 0.018" rpy="1.57 0 0"/>
	    <axis xyz="0 0 1"></axis>
	    <limit effort="3.1" lower="-1.57" upper="1.57" velocity="7.0"></limit>
  	</joint>
	
	<link name="r_shoulder_pitch">
		<inertial>
			<origin xyz="0 0 0" rpy="0 0 0"></origin>
			<mass value="0.1"></mass>
			<inertia ixx="0.000444379589701896" ixy="0" ixz="0" iyy="0.00048561348802354" iyz="0" izz="0.000421911604661064"></inertia>
		</inertial>
		<visual>
			<origin xyz="0 0 0" rpy="0 0 0"></origin>
			<geometry>
				<cylinder length="0.1" radius="0.01"/>
			</geometry>
			<material name="green"/>
		</visual>
		<collision>
			<origin xyz="0 0 0" rpy="0 0 0"></origin>
			<geometry>
				<cylinder length="0.1" radius="0.01"/>
			</geometry>
		</collision>
	</link>
	
	<joint name="r_shoulder_pitch_to_upper_arm" type="fixed">
	    <parent link="r_shoulder_pitch"/>
	    <child link="r_upper_arm"/>
	    <origin xyz="0 0.075 0" rpy="0 0 0"/>
	    <axis xyz="0 0 1"></axis>
  	</joint>
	
	<link name="r_upper_arm">
		<inertial>
			<origin xyz="0 0 0" rpy="0 0 0"></origin>
			<mass value="0.1"></mass>
			<inertia ixx="0.000444379589701896" ixy="0" ixz="0" iyy="0.00048561348802354" iyz="0" izz="0.000421911604661064"></inertia>
		</inertial>
		<visual>
			<origin xyz="0 0 0" rpy="0 0 0"></origin>
			<geometry>
				<box size="0.03 0.15 0.05"/>
			</geometry>
			<material name="white"/>
		</visual>
		<collision>
			<origin xyz="0 0 0" rpy="0 0 0"></origin>
			<geometry>
				<box size="0.03 0.1 0.05"/>
			</geometry>
		</collision>
	</link>
	
	<joint name="r_upper_arm_to_elbow" type="revolute">
	    <parent link="r_upper_arm"/>
	    <child link="r_elbow"/>
	    <origin xyz="0 0.08 0" rpy="0 -1.57 0"/>
	    <axis xyz="0 0 1"></axis>
	    <limit effort="3.1" lower="-.57" upper="1.57" velocity="7.0"></limit>
  	</joint>
	
	<link name="r_elbow">
		<inertial>
			<origin xyz="0 0 0" rpy="0 0 0"></origin>
			<mass value="0.1"></mass>
			<inertia ixx="0.000444379589701896" ixy="0" ixz="0" iyy="0.00048561348802354" iyz="0" izz="0.000421911604661064"></inertia>
		</inertial>
		<visual>
			<origin xyz="0 0 0" rpy="0 0 0"></origin>
			<geometry>
				<cylinder length="0.075" radius="0.01"/>
			</geometry>
			<material name="blue"/>
		</visual>
		<collision>
			<origin xyz="0 0 0" rpy="0 0 0"></origin>
			<geometry>
				<cylinder length="0.075" radius="0.01"/>
			</geometry>
		</collision>
	</link>
	
	<joint name="r_elbow_to_forearm" type="fixed">
	    <parent link="r_elbow"/>
	    <child link="r_forearm"/>
	    <origin xyz="0 0.08 0" rpy="0 0 0"/>
	    <axis xyz="0 0 1"></axis>
  	</joint>
	
	<link name="r_forearm">
		<inertial>
			<origin xyz="0 0 0" rpy="0 0 0"></origin>
			<mass value="0.1"></mass>
			<inertia ixx="0.000444379589701896" ixy="0" ixz="0" iyy="0.00048561348802354" iyz="0" izz="0.000421911604661064"></inertia>
		</inertial>
		<visual>
			<origin xyz="0 0 0" rpy="0 0 0"></origin>
			<geometry>
				<box size="0.03 0.15 0.05"/>
			</geometry>
			<material name="white"/>
		</visual>
		<collision>
			<origin xyz="0 0 0" rpy="0 0 0"></origin>
			<geometry>
				<box size="0.03 0.15 0.05"/>
			</geometry>
		</collision>
	</link>
	
	<joint name="r_forearm_to_wrist_1" type="revolute">
	    <parent link="r_forearm"/>
	    <child link="r_wrist_1"/>
	    <origin xyz="0 0.08 0" rpy="0 0 0"/>
	    <axis xyz="0 0 1"></axis>
	    <limit effort="3.1" lower="-1.57" upper="1.57" velocity="7.0"></limit>
  	</joint>
	
	<link name="r_wrist_1">
		<inertial>
			<origin xyz="0 0 0" rpy="0 0 0"></origin>
			<mass value="0.1"></mass>
			<inertia ixx="0.000444379589701896" ixy="0" ixz="0" iyy="0.00048561348802354" iyz="0" izz="0.000421911604661064"></inertia>
		</inertial>
		<visual>
			<origin xyz="0 0 0" rpy="0 0 0"></origin>
			<geometry>
				<cylinder length="0.05" radius="0.01"/>
			</geometry>
			<material name="blue"/>
		</visual>
		<collision>
			<origin xyz="0 0 0" rpy="0 0 0"></origin>
			<geometry>
				<cylinder length="0.05" radius="0.01"/>
			</geometry>
		</collision>
	</link>
	
	<joint name="r_wrist_1_to_wrist_2" type="revolute">
	    <parent link="r_wrist_1"/>
	    <child link="r_wrist_2"/>
	    <origin xyz="0 0.02 0" rpy="0 -1.57 0"/>
	    <axis xyz="0 0 1"></axis>
	    <limit effort="3.1" lower="-1.57" upper="1.57" velocity="7.0"></limit>
  	</joint>
	
	<link name="r_wrist_2">
		<inertial>
			<origin xyz="0 0 0" rpy="0 0 0"></origin>
			<mass value="0.1"></mass>
			<inertia ixx="0.000444379589701896" ixy="0" ixz="0" iyy="0.00048561348802354" iyz="0" izz="0.000421911604661064"></inertia>
		</inertial>
		<visual>
			<origin xyz="0 0 0" rpy="0 0 0"></origin>
			<geometry>
				<cylinder length="0.03" radius="0.01"/>
			</geometry>
			<material name="green"/>
		</visual>
		<collision>
			<origin xyz="0 0 0" rpy="0 0 0"></origin>
			<geometry>
				<cylinder length="0.03" radius="0.01"/>
			</geometry>
		</collision>
	</link>
	
	<joint name="r_wrist_2_to_hand" type="fixed">
	    <parent link="r_wrist_2"/>
	    <child link="r_hand"/>
	    <origin xyz="0 0.04 0" rpy="0 0 0"/>
	    <axis xyz="0 0 1"></axis>
  	</joint>
	
	<link name="r_hand">
		<inertial>
			<origin xyz="0 0 0" rpy="0 0 0"></origin>
			<mass value="0.1"></mass>
			<inertia ixx="0.000444379589701896" ixy="0" ixz="0" iyy="0.00048561348802354" iyz="0" izz="0.000421911604661064"></inertia>
		</inertial>
		<visual>
			<origin xyz="0 0 0" rpy="0 0 0"></origin>
			<geometry>
				<sphere radius="0.03"/>
			</geometry>
			<material name="red"/>
		</visual>
		<collision>
			<origin xyz="0 0 0" rpy="0 0 0"></origin>
			<geometry>
				<sphere radius="0.03"/>
			</geometry>
		</collision>
	</link>
	
	<joint name="r_end_effector" type="fixed">
	    <parent link="r_hand"/>
	    <child link="r_ee_link"/>
	    <origin xyz="0 0 0" rpy="0 0 0"/>
	    <axis xyz="0 0 1"></axis>
  	</joint>
  	
  	<link name="r_ee_link">
        <inertial>
          <mass value="0.001" />
          <inertia ixx="0.0001" iyy="0.0001" izz="0.0001" ixy="0" ixz="0" iyz="0" />
        </inertial>
      </link>
      
      
      
      
      
      
      
      <joint name="base_to_l_shoulder_yaw" type="revolute">
	    <parent link="base"/>
	    <child link="l_shoulder_yaw"/>
	    <origin xyz="-0.16 0. 0.15" rpy="0 0 0"/>
	    <axis xyz="0 0 -1"></axis>
	    <limit effort="3.1" lower="-1.57" upper="1.57" velocity="7.0"></limit>
  	</joint>
	
	<link name="l_shoulder_yaw">
		<inertial>
			<origin xyz="0 0 0" rpy="0 0 0"></origin>
			<mass value="0.1"></mass>
			<inertia ixx="0.000444379589701896" ixy="0" ixz="0" iyy="0.00048561348802354" iyz="0" izz="0.000421911604661064"></inertia>
		</inertial>
		<visual>
			<origin xyz="0 0 0" rpy="0 0 0"></origin>
			<geometry>
				<cylinder length="0.1" radius="0.01"/>
			</geometry>
			<material name="blue"/>
		</visual>
		<collision>
			<origin xyz="0 0 0" rpy="0 0 0"></origin>
			<geometry>
				<cylinder length="0.1" radius="0.01"/>
			</geometry>
		</collision>
	</link>
	
	<joint name="l_shoulder_yaw_to_shoulder_roll" type="revolute">
	    <parent link="l_shoulder_yaw"/>
	    <child link="l_shoulder_roll"/>
	    <origin xyz="-0.018 0 0" rpy="0 -1.57 0"/>
	    <axis xyz="0 0 -1"></axis>
	    <limit effort="3.1" lower="-1.57" upper="1.57" velocity="7.0"></limit>
  	</joint>
	
	<link name="l_shoulder_roll">
		<inertial>
			<origin xyz="0 0 0" rpy="0 0 0"></origin>
			<mass value="0.1"></mass>
			<inertia ixx="0.000444379589701896" ixy="0" ixz="0" iyy="0.00048561348802354" iyz="0" izz="0.000421911604661064"></inertia>
		</inertial>
		<visual>
			<origin xyz="0 0 0" rpy="0 0 0"></origin>
			<geometry>
				<cylinder length="0.01" radius="0.05"/>
			</geometry>
			<material name="black"/>
		</visual>
		<collision>
			<origin xyz="0 0 0" rpy="0 0 0"></origin>
			<geometry>
				<cylinder length="0.01" radius="0.05"/>
			</geometry>
		</collision>
	</link>
	
	<joint name="l_shoulder_roll_to_shoulder_pitch" type="revolute">
	    <parent link="l_shoulder_roll"/>
	    <child link="l_shoulder_pitch"/>
	    <origin xyz="0 0 0.018" rpy="1.57 0 0"/>
	    <axis xyz="0 0 -1"></axis>
	    <limit effort="3.1" lower="-1.57" upper="1.57" velocity="7.0"></limit>
  	</joint>
	
	<link name="l_shoulder_pitch">
		<inertial>
			<origin xyz="0 0 0" rpy="0 0 0"></origin>
			<mass value="0.1"></mass>
			<inertia ixx="0.000444379589701896" ixy="0" ixz="0" iyy="0.00048561348802354" iyz="0" izz="0.000421911604661064"></inertia>
		</inertial>
		<visual>
			<origin xyz="0 0 0" rpy="0 0 0"></origin>
			<geometry>
				<cylinder length="0.1" radius="0.01"/>
			</geometry>
			<material name="green"/>
		</visual>
		<collision>
			<origin xyz="0 0 0" rpy="0 0 0"></origin>
			<geometry>
				<cylinder length="0.1" radius="0.01"/>
			</geometry>
		</collision>
	</link>
	
	<joint name="l_shoulder_pitch_to_upper_arm" type="fixed">
	    <parent link="l_shoulder_pitch"/>
	    <child link="l_upper_arm"/>
	    <origin xyz="0 0.075 0" rpy="0 0 0"/>
	    <axis xyz="0 0 1"></axis>
  	</joint>
	
	<link name="l_upper_arm">
		<inertial>
			<origin xyz="0 0 0" rpy="0 0 0"></origin>
			<mass value="0.1"></mass>
			<inertia ixx="0.000444379589701896" ixy="0" ixz="0" iyy="0.00048561348802354" iyz="0" izz="0.000421911604661064"></inertia>
		</inertial>
		<visual>
			<origin xyz="0 0 0" rpy="0 0 0"></origin>
			<geometry>
				<box size="0.03 0.15 0.05"/>
			</geometry>
			<material name="white"/>
		</visual>
		<collision>
			<origin xyz="0 0 0" rpy="0 0 0"></origin>
			<geometry>
				<box size="0.03 0.1 0.05"/>
			</geometry>
		</collision>
	</link>
	
	<joint name="l_upper_arm_to_elbow" type="revolute">
	    <parent link="l_upper_arm"/>
	    <child link="l_elbow"/>
	    <origin xyz="0 0.08 0" rpy="0 1.57 0"/>
	    <axis xyz="0 0 -1"></axis>
	    <limit effort="3.1" lower="-1.57" upper="1.57" velocity="7.0"></limit>
  	</joint>
	
	<link name="l_elbow">
		<inertial>
			<origin xyz="0 0 0" rpy="0 0 0"></origin>
			<mass value="0.1"></mass>
			<inertia ixx="0.000444379589701896" ixy="0" ixz="0" iyy="0.00048561348802354" iyz="0" izz="0.000421911604661064"></inertia>
		</inertial>
		<visual>
			<origin xyz="0 0 0" rpy="0 0 0"></origin>
			<geometry>
				<cylinder length="0.075" radius="0.01"/>
			</geometry>
			<material name="blue"/>
		</visual>
		<collision>
			<origin xyz="0 0 0" rpy="0 0 0"></origin>
			<geometry>
				<cylinder length="0.075" radius="0.01"/>
			</geometry>
		</collision>
	</link>
	
	<joint name="l_elbow_to_forearm" type="fixed">
	    <parent link="l_elbow"/>
	    <child link="l_forearm"/>
	    <origin xyz="0 0.08 0" rpy="0 0 0"/>
	    <axis xyz="0 0 1"></axis>
  	</joint>
	
	<link name="l_forearm">
		<inertial>
			<origin xyz="0 0 0" rpy="0 0 0"></origin>
			<mass value="0.1"></mass>
			<inertia ixx="0.000444379589701896" ixy="0" ixz="0" iyy="0.00048561348802354" iyz="0" izz="0.000421911604661064"></inertia>
		</inertial>
		<visual>
			<origin xyz="0 0 0" rpy="0 0 0"></origin>
			<geometry>
				<box size="0.03 0.15 0.05"/>
			</geometry>
			<material name="white"/>
		</visual>
		<collision>
			<origin xyz="0 0 0" rpy="0 0 0"></origin>
			<geometry>
				<box size="0.03 0.1 0.05"/>
			</geometry>
		</collision>
	</link>
	
	<joint name="l_forearm_to_wrist_1" type="revolute">
	    <parent link="l_forearm"/>
	    <child link="l_wrist_1"/>
	    <origin xyz="0 0.08 0" rpy="0 0 0"/>
	    <axis xyz="0 0 -1"></axis>
	    <limit effort="3.1" lower="-1.57" upper="1.57" velocity="7.0"></limit>
  	</joint>
	
	<link name="l_wrist_1">
		<inertial>
			<origin xyz="0 0 0" rpy="0 0 0"></origin>
			<mass value="0.1"></mass>
			<inertia ixx="0.000444379589701896" ixy="0" ixz="0" iyy="0.00048561348802354" iyz="0" izz="0.000421911604661064"></inertia>
		</inertial>
		<visual>
			<origin xyz="0 0 0" rpy="0 0 0"></origin>
			<geometry>
				<cylinder length="0.05" radius="0.01"/>
			</geometry>
			<material name="blue"/>
		</visual>
		<collision>
			<origin xyz="0 0 0" rpy="0 0 0"></origin>
			<geometry>
				<cylinder length="0.05" radius="0.01"/>
			</geometry>
		</collision>
	</link>
	
	<joint name="l_wrist_1_to_wrist_2" type="revolute">
	    <parent link="l_wrist_1"/>
	    <child link="l_wrist_2"/>
	    <origin xyz="0 0.02 0" rpy="0 -1.57 0"/>
	    <axis xyz="0 0 1"></axis>
	    <limit effort="3.1" lower="-1.57" upper="1.57" velocity="7.0"></limit>
  	</joint>
	
	<link name="l_wrist_2">
		<inertial>
			<origin xyz="0 0 0" rpy="0 0 0"></origin>
			<mass value="0.1"></mass>
			<inertia ixx="0.000444379589701896" ixy="0" ixz="0" iyy="0.00048561348802354" iyz="0" izz="0.000421911604661064"></inertia>
		</inertial>
		<visual>
			<origin xyz="0 0 0" rpy="0 0 0"></origin>
			<geometry>
				<cylinder length="0.03" radius="0.01"/>
			</geometry>
			<material name="green"/>
		</visual>
		<collision>
			<origin xyz="0 0 0" rpy="0 0 0"></origin>
			<geometry>
				<cylinder length="0.03" radius="0.01"/>
			</geometry>
		</collision>
	</link>
	
	<joint name="l_wrist_2_to_hand" type="fixed">
	    <parent link="l_wrist_2"/>
	    <child link="l_hand"/>
	    <origin xyz="0 0.04 0" rpy="0 0 0"/>
	    <axis xyz="0 0 1"></axis>
  	</joint>
	
	<link name="l_hand">
		<inertial>
			<origin xyz="0 0 0" rpy="0 0 0"></origin>
			<mass value="0.1"></mass>
			<inertia ixx="0.000444379589701896" ixy="0" ixz="0" iyy="0.00048561348802354" iyz="0" izz="0.000421911604661064"></inertia>
		</inertial>
		<visual>
			<origin xyz="0 0 0" rpy="0 0 0"></origin>
			<geometry>
				<sphere radius="0.03"/>
			</geometry>
			<material name="red"/>
		</visual>
		<collision>
			<origin xyz="0 0 0" rpy="0 0 0"></origin>
			<geometry>
				<sphere radius="0.03"/>
			</geometry>
		</collision>
	</link>
	
	<joint name="l_end_effector" type="fixed">
	    <parent link="l_hand"/>
	    <child link="l_ee_link"/>
	    <origin xyz="0 0 0" rpy="0 0 0"/>
	    <axis xyz="0 0 1"></axis>
  	</joint>
  	
  	<link name="l_ee_link">
        <inertial>
          <mass value="0.001" />
          <inertia ixx="0.0001" iyy="0.0001" izz="0.0001" ixy="0" ixz="0" iyz="0" />
        </inertial>
      </link>
	
	
	
	
	
	
</robot>
