<?xml version="1.0" encoding="utf-8"?>
<robot name="Custom_Upper_Body">


	  <material name="blue">
	    	<color rgba="0 0 0.8 1"/>
	  </material>
	  <material name="black">
	    	<color rgba="0 0 0 1"/>
	  </material>
	  <material name="white">
	    	<color rgba="1 1 1 1"/>
	  </material>
  	<material name="red">
    		<color rgba="0.8 0 0 1"/>
  	</material>
  	<material name="green">
    		<color rgba="0 0.8 0 1"/>
  	</material>
  	
  	
	<link name="base">
		<mass value="0.3"/>
		<inertial>
			<origin xyz="0 0 0" rpy="0 0 0"></origin>
			<mass value="0.3"></mass>
			<inertia ixx="0.000444379589701896" ixy="0" ixz="0" iyy="0.00048561348802354" iyz="0" izz="0.000421911604661064"></inertia>
		</inertial>
		<visual>
			<origin xyz="0 0 0" rpy="0 0 0"></origin>
			<geometry>
				<box size="0.3 0.15 0.4"/>
			</geometry>
			<material name="white"/>
		</visual>
		<collision>
			<origin xyz="0 0 0" rpy="0 0 0"></origin>
			<geometry>
				<box size="0.3 0.15 0.4"/>
			</geometry>
		</collision>
	</link>
	
	<joint name="z_base_to_r_hip_yaw" type="revolute">
	    <parent link="base"/>
	    <child link="r_hip_yaw"/>
	    <origin xyz="0.1 0. -0.205" rpy="0 0 0"/>
	    <axis xyz="0 0 -1"></axis>
	    <limit effort="3.1" lower="-1.57" upper="1.57" velocity="7.0"></limit>
  	</joint>
	
	<link name="r_hip_yaw">
		<inertial>
			<origin xyz="0 0 0" rpy="0 0 0"></origin>
			<mass value="0.1"></mass>
			<inertia ixx="0.000444379589701896" ixy="0" ixz="0" iyy="0.00048561348802354" iyz="0" izz="0.000421911604661064"></inertia>
		</inertial>
		<visual>
			<origin xyz="0 0 0" rpy="0 0 0"></origin>
			<geometry>
				<cylinder length="0.01" radius="0.05"/>
			</geometry>
			<material name="blue"/>
		</visual>
		<collision>
			<origin xyz="0 0 0" rpy="0 0 0"></origin>
			<geometry>
				<cylinder length="0.1" radius="0.01"/>
			</geometry>
		</collision>
	</link> 
	
	<joint name="r_hip_yaw_to_pitch" type="revolute">
	    <parent link="r_hip_yaw"/>
	    <child link="r_hip_pitch"/>
	    <origin xyz="0. 0. -0.015" rpy="1.57 0 0"/>
	    <axis xyz="0 0 1"></axis>
	    <limit effort="3.1" lower="-1.57" upper="1.57" velocity="7.0"></limit>
  	</joint>
	
	<link name="r_hip_pitch">
		<inertial>
			<origin xyz="0 0 0" rpy="0 0 0"></origin>
			<mass value="0.1"></mass>
			<inertia ixx="0.000444379589701896" ixy="0" ixz="0" iyy="0.00048561348802354" iyz="0" izz="0.000421911604661064"></inertia>
		</inertial>
		<visual>
			<origin xyz="0 0 0" rpy="0 0 0"></origin>
			<geometry>
				<cylinder length="0.1" radius="0.01"/>
			</geometry>
			<material name="green"/>
		</visual>
		<collision>
			<origin xyz="0 0 0" rpy="0 0 0"></origin>
			<geometry>
				<cylinder length="0.1" radius="0.01"/>
			</geometry>
		</collision>
	</link>
	
	<joint name="r_hip_pitch_to_roll" type="revolute">
	    <parent link="r_hip_pitch"/>
	    <child link="r_hip_roll"/>
	    <origin xyz="0. -0.02 0." rpy="0 1.57 0"/>
	    <axis xyz="0 0 1"></axis>
	    <limit effort="3.1" lower="-1.57" upper="1.57" velocity="7.0"></limit>
  	</joint>
	
	<link name="r_hip_roll">
		<inertial>
			<origin xyz="0 0 0" rpy="0 0 0"></origin>
			<mass value="0.1"></mass>
			<inertia ixx="0.000444379589701896" ixy="0" ixz="0" iyy="0.00048561348802354" iyz="0" izz="0.000421911604661064"></inertia>
		</inertial>
		<visual>
			<origin xyz="0 0 0" rpy="0 0 0"></origin>
			<geometry>
				<cylinder length="0.1" radius="0.01"/>
			</geometry>
			<material name="black"/>
		</visual>
		<collision>
			<origin xyz="0 0 0" rpy="0 0 0"></origin>
			<geometry>
				<cylinder length="0.1" radius="0.01"/>
			</geometry>
		</collision>
	</link>
	
	<joint name="r_hip_roll_to_upper_leg" type="fixed">
	    <parent link="r_hip_roll"/>
	    <child link="r_upper_leg"/>
	    <origin xyz="0 -0.08 0" rpy="0 0 0"/>
	    <axis xyz="0 0 1"></axis>
  	</joint>
	
	<link name="r_upper_leg">
		<inertial>
			<origin xyz="0 0 0" rpy="0 0 0"></origin>
			<mass value="0.1"></mass>
			<inertia ixx="0.000444379589701896" ixy="0" ixz="0" iyy="0.00048561348802354" iyz="0" izz="0.000421911604661064"></inertia>
		</inertial>
		<visual>
			<origin xyz="0 0 0" rpy="0 0 0"></origin>
			<geometry>
				<box size="0.03 0.15 0.05"/>
			</geometry>
			<material name="white"/>
		</visual>
		<collision>
			<origin xyz="0 0 0" rpy="0 0 0"></origin>
			<geometry>
				<box size="0.03 0.1 0.05"/>
			</geometry>
		</collision>
	</link>
	
	
	<joint name="r_upper_leg_to_knee" type="revolute">
	    <parent link="r_upper_leg"/>
	    <child link="r_knee"/>
	    <origin xyz="0 -0.08 0" rpy="0 0 0"/>
	    <axis xyz="0 0 -1"></axis>
	    <limit effort="3.1" lower="-.57" upper="1.57" velocity="7.0"></limit>
  	</joint>
	
	<link name="r_knee">
		<inertial>
			<origin xyz="0 0 0" rpy="0 0 0"></origin>
			<mass value="0.1"></mass>
			<inertia ixx="0.000444379589701896" ixy="0" ixz="0" iyy="0.00048561348802354" iyz="0" izz="0.000421911604661064"></inertia>
		</inertial>
		<visual>
			<origin xyz="0 0 0" rpy="0 0 0"></origin>
			<geometry>
				<cylinder length="0.075" radius="0.01"/>
			</geometry>
			<material name="black"/>
		</visual>
		<collision>
			<origin xyz="0 0 0" rpy="0 0 0"></origin>
			<geometry>
				<cylinder length="0.075" radius="0.01"/>
			</geometry>
		</collision>
	</link>
	
	<joint name="r_knee_to_lower_leg" type="fixed">
	    <parent link="r_knee"/>
	    <child link="r_lower_leg"/>
	    <origin xyz="0 -0.08 0" rpy="0 0 0"/>
	    <axis xyz="0 0 1"></axis>
  	</joint>
	
	<link name="r_lower_leg">
		<inertial>
			<origin xyz="0 0 0" rpy="0 0 0"></origin>
			<mass value="0.1"></mass>
			<inertia ixx="0.000444379589701896" ixy="0" ixz="0" iyy="0.00048561348802354" iyz="0" izz="0.000421911604661064"></inertia>
		</inertial>
		<visual>
			<origin xyz="0 0 0" rpy="0 0 0"></origin>
			<geometry>
				<box size="0.03 0.15 0.05"/>
			</geometry>
			<material name="white"/>
		</visual>
		<collision>
			<origin xyz="0 0 0" rpy="0 0 0"></origin>
			<geometry>
				<box size="0.03 0.1 0.05"/>
			</geometry>
		</collision>
	</link>
	
	<joint name="r_lower_leg_to_ankle" type="revolute">
	    <parent link="r_lower_leg"/>
	    <child link="r_ankle"/>
	    <origin xyz="0 -0.08 0" rpy="0 1.57 0"/>
	    <axis xyz="0 0 -1"></axis>
	    <limit effort="3.1" lower="-.57" upper="1.57" velocity="7.0"></limit>
  	</joint>
	
	<link name="r_ankle">
		<inertial>
			<origin xyz="0 0 0" rpy="0 0 0"></origin>
			<mass value="0.1"></mass>
			<inertia ixx="0.000444379589701896" ixy="0" ixz="0" iyy="0.00048561348802354" iyz="0" izz="0.000421911604661064"></inertia>
		</inertial>
		<visual>
			<origin xyz="0 0 0" rpy="0 0 0"></origin>
			<geometry>
				<cylinder length="0.05" radius="0.01"/>
			</geometry>
			<material name="green"/>
		</visual>
		<collision>
			<origin xyz="0 0 0" rpy="0 0 0"></origin>
			<geometry>
				<cylinder length="0.05" radius="0.01"/>
			</geometry>
		</collision>
	</link>
	
	
	<joint name="r_ankle_to_foot" type="fixed">
	    <parent link="r_ankle"/>
	    <child link="r_foot"/>
	    <origin xyz="0 -0.025 0.02" rpy="0 0 0"/>
	    <axis xyz="0 0 1"></axis>
  	</joint>
	
	<link name="r_foot">
		<inertial>
			<origin xyz="0 0 0" rpy="0 0 0"></origin>
			<mass value="0.1"></mass>
			<inertia ixx="0.000444379589701896" ixy="0" ixz="0" iyy="0.00048561348802354" iyz="0" izz="0.000421911604661064"></inertia>
		</inertial>
		<visual>
			<origin xyz="0 0 0" rpy="0 0 0"></origin>
			<geometry>
				<box size="0.06 0.03 0.12"/>
			</geometry>
			<material name="red"/>
		</visual>
		<collision>
			<origin xyz="0 0 0" rpy="0 0 0"></origin>
			<geometry>
				<box size="0.06 0.03 0.1"/>
			</geometry>
		</collision>
	</link>
	
	<joint name="r_foot_end_effector" type="fixed">
	    <parent link="r_foot"/>
	    <child link="r_foot_ee_link"/>
	    <origin xyz="0 0 0" rpy="0 0 0"/>
	    <axis xyz="0 0 1"></axis>
  	</joint>
  	
  	<link name="r_foot_ee_link">
        <inertial>
          <mass value="0.001" />
          <inertia ixx="0.0001" iyy="0.0001" izz="0.0001" ixy="0" ixz="0" iyz="0" />
        </inertial>
      </link>
	
	
	
	<joint name="z_base_to_l_hip_yaw" type="revolute">
	    <parent link="base"/>
	    <child link="l_hip_yaw"/>
	    <origin xyz="-0.1 0. -0.205" rpy="0 0 0"/>
	    <axis xyz="0 0 -1"></axis>
	    <limit effort="3.1" lower="-1.57" upper="1.57" velocity="7.0"></limit>
  	</joint>
	
	<link name="l_hip_yaw">
		<inertial>
			<origin xyz="0 0 0" rpy="0 0 0"></origin>
			<mass value="0.1"></mass>
			<inertia ixx="0.000444379589701896" ixy="0" ixz="0" iyy="0.00048561348802354" iyz="0" izz="0.000421911604661064"></inertia>
		</inertial>
		<visual>
			<origin xyz="0 0 0" rpy="0 0 0"></origin>
			<geometry>
				<cylinder length="0.01" radius="0.05"/>
			</geometry>
			<material name="blue"/>
		</visual>
		<collision>
			<origin xyz="0 0 0" rpy="0 0 0"></origin>
			<geometry>
				<cylinder length="0.1" radius="0.01"/>
			</geometry>
		</collision>
	</link> 
	
	<joint name="l_hip_yaw_to_pitch" type="revolute">
	    <parent link="l_hip_yaw"/>
	    <child link="l_hip_pitch"/>
	    <origin xyz="0. 0. -0.015" rpy="1.57 0 0"/>
	    <axis xyz="0 0 1"></axis>
	    <limit effort="3.1" lower="-1.57" upper="1.57" velocity="7.0"></limit>
  	</joint>
	
	<link name="l_hip_pitch">
		<inertial>
			<origin xyz="0 0 0" rpy="0 0 0"></origin>
			<mass value="0.1"></mass>
			<inertia ixx="0.000444379589701896" ixy="0" ixz="0" iyy="0.00048561348802354" iyz="0" izz="0.000421911604661064"></inertia>
		</inertial>
		<visual>
			<origin xyz="0 0 0" rpy="0 0 0"></origin>
			<geometry>
				<cylinder length="0.1" radius="0.01"/>
			</geometry>
			<material name="green"/>
		</visual>
		<collision>
			<origin xyz="0 0 0" rpy="0 0 0"></origin>
			<geometry>
				<cylinder length="0.1" radius="0.01"/>
			</geometry>
		</collision>
	</link>
	
	<joint name="l_hip_pitch_to_roll" type="revolute">
	    <parent link="l_hip_pitch"/>
	    <child link="l_hip_roll"/>
	    <origin xyz="0. -0.02 0." rpy="0 1.57 0"/>
	    <axis xyz="0 0 1"></axis>
	    <limit effort="3.1" lower="-1.57" upper="1.57" velocity="7.0"></limit>
  	</joint>
	
	<link name="l_hip_roll">
		<inertial>
			<origin xyz="0 0 0" rpy="0 0 0"></origin>
			<mass value="0.1"></mass>
			<inertia ixx="0.000444379589701896" ixy="0" ixz="0" iyy="0.00048561348802354" iyz="0" izz="0.000421911604661064"></inertia>
		</inertial>
		<visual>
			<origin xyz="0 0 0" rpy="0 0 0"></origin>
			<geometry>
				<cylinder length="0.1" radius="0.01"/>
			</geometry>
			<material name="black"/>
		</visual>
		<collision>
			<origin xyz="0 0 0" rpy="0 0 0"></origin>
			<geometry>
				<cylinder length="0.1" radius="0.01"/>
			</geometry>
		</collision>
	</link>
	
	<joint name="l_hip_roll_to_upper_leg" type="fixed">
	    <parent link="l_hip_roll"/>
	    <child link="l_upper_leg"/>
	    <origin xyz="0 -0.08 0" rpy="0 0 0"/>
	    <axis xyz="0 0 1"></axis>
  	</joint>
	
	<link name="l_upper_leg">
		<inertial>
			<origin xyz="0 0 0" rpy="0 0 0"></origin>
			<mass value="0.1"></mass>
			<inertia ixx="0.000444379589701896" ixy="0" ixz="0" iyy="0.00048561348802354" iyz="0" izz="0.000421911604661064"></inertia>
		</inertial>
		<visual>
			<origin xyz="0 0 0" rpy="0 0 0"></origin>
			<geometry>
				<box size="0.03 0.15 0.05"/>
			</geometry>
			<material name="white"/>
		</visual>
		<collision>
			<origin xyz="0 0 0" rpy="0 0 0"></origin>
			<geometry>
				<box size="0.03 0.1 0.05"/>
			</geometry>
		</collision>
	</link>
	
	
	<joint name="l_upper_leg_to_knee" type="revolute">
	    <parent link="l_upper_leg"/>
	    <child link="l_knee"/>
	    <origin xyz="0 -0.08 0" rpy="0 0 0"/>
	    <axis xyz="0 0 -1"></axis>
	    <limit effort="3.1" lower="-1.57" upper="1.57" velocity="7.0"></limit>
  	</joint>
	
	<link name="l_knee">
		<inertial>
			<origin xyz="0 0 0" rpy="0 0 0"></origin>
			<mass value="0.1"></mass>
			<inertia ixx="0.000444379589701896" ixy="0" ixz="0" iyy="0.00048561348802354" iyz="0" izz="0.000421911604661064"></inertia>
		</inertial>
		<visual>
			<origin xyz="0 0 0" rpy="0 0 0"></origin>
			<geometry>
				<cylinder length="0.075" radius="0.01"/>
			</geometry>
			<material name="black"/>
		</visual>
		<collision>
			<origin xyz="0 0 0" rpy="0 0 0"></origin>
			<geometry>
				<cylinder length="0.075" radius="0.01"/>
			</geometry>
		</collision>
	</link>
	
	<joint name="l_knee_to_lower_leg" type="fixed">
	    <parent link="l_knee"/>
	    <child link="l_lower_leg"/>
	    <origin xyz="0 -0.08 0" rpy="0 0 0"/>
	    <axis xyz="0 0 1"></axis>
  	</joint>
	
	<link name="l_lower_leg">
		<inertial>
			<origin xyz="0 0 0" rpy="0 0 0"></origin>
			<mass value="0.1"></mass>
			<inertia ixx="0.000444379589701896" ixy="0" ixz="0" iyy="0.00048561348802354" iyz="0" izz="0.000421911604661064"></inertia>
		</inertial>
		<visual>
			<origin xyz="0 0 0" rpy="0 0 0"></origin>
			<geometry>
				<box size="0.03 0.15 0.05"/>
			</geometry>
			<material name="white"/>
		</visual>
		<collision>
			<origin xyz="0 0 0" rpy="0 0 0"></origin>
			<geometry>
				<box size="0.03 0.1 0.05"/>
			</geometry>
		</collision>
	</link>
	
	<joint name="l_lower_leg_to_ankle" type="revolute">
	    <parent link="l_lower_leg"/>
	    <child link="l_ankle"/>
	    <origin xyz="0 -0.08 0" rpy="0 1.57 0"/>
	    <axis xyz="0 0 -1"></axis>
	    <limit effort="3.1" lower="-1.57" upper="1.57" velocity="7.0"></limit>
  	</joint>
	
	<link name="l_ankle">
		<inertial>
			<origin xyz="0 0 0" rpy="0 0 0"></origin>
			<mass value="0.1"></mass>
			<inertia ixx="0.000444379589701896" ixy="0" ixz="0" iyy="0.00048561348802354" iyz="0" izz="0.000421911604661064"></inertia>
		</inertial>
		<visual>
			<origin xyz="0 0 0" rpy="0 0 0"></origin>
			<geometry>
				<cylinder length="0.05" radius="0.01"/>
			</geometry>
			<material name="green"/>
		</visual>
		<collision>
			<origin xyz="0 0 0" rpy="0 0 0"></origin>
			<geometry>
				<cylinder length="0.05" radius="0.01"/>
			</geometry>
		</collision>
	</link>
	
	
	<joint name="l_ankle_to_foot" type="fixed">
	    <parent link="l_ankle"/>
	    <child link="l_foot"/>
	    <origin xyz="0 -0.025 0.02" rpy="0 0 0"/>
	    <axis xyz="0 0 1"></axis>
  	</joint>
	
	<link name="l_foot">
		<inertial>
			<origin xyz="0 0 0" rpy="0 0 0"></origin>
			<mass value="0.1"></mass>
			<inertia ixx="0.000444379589701896" ixy="0" ixz="0" iyy="0.00048561348802354" iyz="0" izz="0.000421911604661064"></inertia>
		</inertial>
		<visual>
			<origin xyz="0 0 0" rpy="0 0 0"></origin>
			<geometry>
				<box size="0.06 0.03 0.12"/>
			</geometry>
			<material name="red"/>
		</visual>
		<collision>
			<origin xyz="0 0 0" rpy="0 0 0"></origin>
			<geometry>
				<box size="0.06 0.03 0.1"/>
			</geometry>
		</collision>
	</link>
	
	<joint name="l_foot_end_effector" type="fixed">
	    <parent link="l_foot"/>
	    <child link="l_foot_ee_link"/>
	    <origin xyz="0 0 0" rpy="0 0 0"/>
	    <axis xyz="0 0 1"></axis>
  	</joint>
  	
  	<link name="l_foot_ee_link">
        <inertial>
          <mass value="0.001" />
          <inertia ixx="0.0001" iyy="0.0001" izz="0.0001" ixy="0" ixz="0" iyz="0" />
        </inertial>
      </link>
	
	
	
	
	
</robot>
