<?xml version="1.0" encoding="utf-8"?>
<!-- This URDF was automatically created by SolidWorks to URDF Exporter! Originally created by Stephen Brawner (brawner@gmail.com) 
     Commit Version: 1.6.0-4-g7f85cfe  Build Version: 1.6.7995.38578
     For more information, please see http://wiki.ros.org/sw_urdf_exporter -->
<robot
  name="Torso Assembly.SLDASM">
  <link
    name="base_link">
    <visual>
      <geometry>
        <box size="0.01 0.01 0.01"/>
      </geometry>
    </visual>
    <collision>
	<origin xyz="0 0 0" rpy="0 0 0"></origin>
	<geometry>
            <box size="0.01 0.01 0.01"/>
      </geometry>
    </collision>
  </link>
  <joint
    name="left_foot_base"
    type="fixed">
    <origin
      xyz="0 0 0"
      rpy="0 0 0" />
    <parent
      link="base_link" />
    <child
      link="left_foot" />
    <axis
      xyz="0 -1 0" />
  </joint> <link
    name="left_foot">
    <inertial>
      <origin
        xyz="-0.00133727005296427 -0.0726242714881676 -0.0359109539426669"
        rpy="0 0 0" />
      <mass
        value="1.139" />
      <inertia
        ixx="0.00297498709595362"
        ixy="-4.09060438851532E-05"
        ixz="1.67262617824272E-05"
        iyy="0.000478785532809298"
        iyz="-0.00014738334516682"
        izz="0.00314592151715108" />
    </inertial>
    <visual>
      <origin
        xyz="0 0 0"
        rpy="0 3.14 0" />
      <geometry>
        <mesh
          filename="meshes/right_foot.STL" />
      </geometry>
      <material
        name="">
        <color
          rgba="0.792156862745098 0.819607843137255 0.933333333333333 1" />
      </material>
    </visual>
    <collision>
      <origin
        xyz="0 0 0"
        rpy="0 0 0" />
      <geometry>
        <mesh
          filename="hitboxes/left_foot.STL" />
      </geometry>
    </collision>
  </link>
  <link
    name="left_ankle">
    <inertial>
      <origin
        xyz="-4.07791969089799E-06 -0.000473272937333305 0.00908241205113625"
        rpy="0 0 0" />
      <mass
        value="0.1" />
      <inertia
        ixx="3.87682873257147E-05"
        ixy="-7.03013197692878E-12"
        ixz="2.64575403966992E-12"
        iyy="4.42522556525815E-05"
        iyz="4.36547915767597E-12"
        izz="5.95308827183769E-05" />
    </inertial>
    <visual>
      <origin
        xyz="0 0 0"
        rpy="0 0 0" />
      <geometry>
        <mesh
          filename="meshes/left_ankle.STL" />
      </geometry>
      <material
        name="">
        <color
          rgba="0.792156862745098 0.819607843137255 0.933333333333333 1" />
      </material>
    </visual>
    <collision>
      <origin
        xyz="0 0 0"
        rpy="0 0 0" />
      <geometry>
        <mesh
          filename="hitboxes/left_ankle.STL" />
      </geometry>
    </collision>
  </link>
  <joint
    name="left_ankle-2"
    type="revolute">
    <origin
      xyz="0 0 0"
      rpy="0 0 0" />
    <parent
      link="left_foot" />
    <child
      link="left_ankle" />
    <axis
      xyz="0 -1 0" />
    <limit
      lower="-1.57"
      upper="1.57"
      effort="100"
      velocity="10" />
  </joint>
  <link
    name="left_lower_leg">
    <inertial>
      <origin
        xyz="0.00101617081533104 -2.29538878978447E-06 0.130891871989569"
        rpy="0 0 0" />
      <mass
        value="1.117" />
      <inertia
        ixx="0.00515989275577796"
        ixy="-1.89701292353525E-07"
        ixz="3.94472481075818E-17"
        iyy="0.00455017622997455"
        iyz="6.01255181337517E-13"
        izz="0.000833155112448721" />
    </inertial>
    <visual>
      <origin
        xyz="0 0 0"
        rpy="0 0 0" />
      <geometry>
        <mesh
          filename="meshes/left_lower_leg.STL" />
      </geometry>
      <material
        name="">
        <color
          rgba="0.792156862745098 0.819607843137255 0.933333333333333 1" />
      </material>
    </visual>
    <collision>
      <origin
        xyz="0 0 0"
        rpy="0 0 0" />
      <geometry>
        <mesh
          filename="hitboxes/left_lower_leg.STL" />
      </geometry>
    </collision>
  </link>
  <joint
    name="left_ankle-1"
    type="revolute">
    <origin
      xyz="-0.001 -0.000470954652436323 0.0227967582282074"
      rpy="0 0 0" />
    <parent
      link="left_ankle" />
    <child
      link="left_lower_leg" />
    <axis
      xyz="-1 0 0" />
    <limit
      lower="-0.523599"
      upper="0.523599"
      effort="100"
      velocity="10" />
  </joint>
  <link
    name="left_upper_leg">
    <inertial>
      <origin
        xyz="-9.40585367681379E-06 -0.00361370895641413 0.189083296589549"
        rpy="0 0 0" />
      <mass
        value="3.189" />
      <inertia
        ixx="0.0148991129480467"
        ixy="-4.01085603845517E-07"
        ixz="3.07010291373221E-07"
        iyy="0.01263954616562"
        iyz="2.03656598390578E-07"
        izz="0.00357733052604832" />
    </inertial>
    <visual>
      <origin
        xyz="0 0 0"
        rpy="0 0 0" />
      <geometry>
        <mesh
          filename="meshes/left_upper_leg.STL" />
      </geometry>
      <material
        name="">
        <color
          rgba="0.792156862745098 0.819607843137255 0.933333333333333 1" />
      </material>
    </visual>
    <collision>
      <origin
        xyz="0 0 0"
        rpy="0 0 0" />
      <geometry>
        <mesh
          filename="hitboxes/left_upper_leg.STL" />
      </geometry>
    </collision>
  </link>
  <joint
    name="left_knee"
    type="revolute">
    <origin
      xyz="-0.000638 0 0.224765554678246"
      rpy="0 0 0" />
    <parent
      link="left_lower_leg" />
    <child
      link="left_upper_leg" />
    <axis
      xyz="-1 0 0" />
    <limit
      lower="0"
      upper="1.57"
      effort="100"
      velocity="10" />
  </joint>
  <link
    name="left_lower_hip">
    <inertial>
      <origin
        xyz="-4.62090918473823E-06 0.000182410443103832 -0.00710606443475131"
        rpy="0 0 0" />
      <mass
        value="1.787" />
      <inertia
        ixx="0.00156616718191446"
        ixy="4.9046944698067E-09"
        ixz="4.64067097674732E-09"
        iyy="0.00324294633204621"
        iyz="-5.54157186687018E-06"
        izz="0.0037046588772097" />
    </inertial>
    <visual>
      <origin
        xyz="0 0 0"
        rpy="0 0 0" />
      <geometry>
        <mesh
          filename="meshes/left_lower_hip.STL" />
      </geometry>
      <material
        name="">
        <color
          rgba="0.792156862745098 0.819607843137255 0.933333333333333 1" />
      </material>
    </visual>
    <collision>
      <origin
        xyz="0 0 0"
        rpy="0 0 0" />
      <geometry>
        <mesh
          filename="hitboxes/left_lower_hip.STL" />
      </geometry>
    </collision>
  </link>
  <joint
    name="left_hip_pitch"
    type="revolute">
    <origin
      xyz="0 -0.00360621292742507 0.320410730513699"
      rpy="0 0 0" />
    <parent
      link="left_upper_leg" />
    <child
      link="left_lower_hip" />
    <axis
      xyz="0 0 1" />
    <limit
      lower="-0.523599"
      upper="1.57"
      effort="100"
      velocity="10" />
  </joint>
  <link
    name="left_mid_hip">
    <inertial>
      <origin
        xyz="-0.00200515792857378 0.0316203124278614 0.00344487456508025"
        rpy="0 0 0" />
      <mass
        value="1.344" />
      <inertia
        ixx="0.00108085497977289"
        ixy="-7.27306551882962E-06"
        ixz="-7.41284296566193E-06"
        iyy="0.00123043251224397"
        iyz="-0.00011554111185679"
        izz="0.00179005564483087" />
    </inertial>
    <visual>
      <origin
        xyz="0 0 0"
        rpy="0 0 0" />
      <geometry>
        <mesh
          filename="meshes/left_mid_hip.STL" />
      </geometry>
      <material
        name="">
        <color
          rgba="0.792156862745098 0.819607843137255 0.933333333333333 1" />
      </material>
    </visual>
    <collision>
      <origin
        xyz="0 0 0"
        rpy="0 0 0" />
      <geometry>
        <mesh
          filename="hitboxes/left_mid_hip.STL" />
      </geometry>
    </collision>
  </link>
  <joint
    name="left_hip_yaw"
    type="revolute">
    <origin
      xyz="0 0.00559886954533739 0.051720828104491"
      rpy="0 0 0" />
    <parent
      link="left_lower_hip" />
    <child
      link="left_mid_hip" />
    <axis
      xyz="0 1 0" />
    <limit
      lower="-0.523599"
      upper="1.57"
      effort="100"
      velocity="10" />
  </joint>
  <link
    name="left_upper_hip">
    <inertial>
      <origin
        xyz="0.0205119006567752 -4.33686872285816E-05 -6.53227018774238E-05"
        rpy="0 0 0" />
      <mass
        value="0.814" />
      <inertia
        ixx="0.000271725673554672"
        ixy="-2.03556985798539E-07"
        ixz="-3.06984692573007E-07"
        iyy="0.000173074208273357"
        iyz="7.40360588494273E-10"
        izz="0.000173712879376846" />
    </inertial>
    <visual>
      <origin
        xyz="0 0 0"
        rpy="0 0 0" />
      <geometry>
        <mesh
          filename="meshes/left_upper_hip.STL" />
      </geometry>
      <material
        name="">
        <color
          rgba="0.792156862745098 0.819607843137255 0.933333333333333 1" />
      </material>
    </visual>
    <collision>
      <origin
        xyz="0 0 0"
        rpy="0 0 0" />
      <geometry>
        <mesh
          filename="hitboxes/left_upper_hip.STL" />
      </geometry>
    </collision>
  </link>
  <joint
    name="left_hip_roll"
    type="revolute">
    <origin
      xyz="-0.123604289139162 -0.00560167902645842 0.000276915207234441"
      rpy="0 0 0" />
    <parent
      link="left_mid_hip" />
    <child
      link="left_upper_hip" />
    <axis
      xyz="1 0 0" />
    <limit
      lower="-0.523599"
      upper="2.0944"
      effort="100"
      velocity="10" />
  </joint>
  <link
    name="torso">
    <inertial>
      <origin
        xyz="-0.0138607 0.0381062620498786 0.293952728467667"
        rpy="0 0 0" />
      <mass
        value="0" />
      <inertia
        ixx="0"
        ixy="0"
        ixz="0"
        iyy="0"
        iyz="0"
        izz="0" />
    </inertial>
    <visual>
      <origin
        xyz="0 0 0"
        rpy="0 0 0" />
      <geometry>
        <mesh
          filename="meshes/torso.STL" />
      </geometry>
      <material
        name="">
        <color
          rgba="0.792156862745098 0.819607843137255 0.933333333333333 1" />
      </material>
    </visual>
    <collision>
      <origin
        xyz="0 0 0"
        rpy="0 0 0" />
      <geometry>
        <mesh
          filename="hitboxes/torso.STL" />
      </geometry>
    </collision>
  </link>
  <link
    name="torso_centre">
    <visual>
      <geometry>
        <box size="0.01 0.01 0.01"/>
      </geometry>
    </visual>
    <collision>
	<origin xyz="0 0 0" rpy="0 0 0"></origin>
	<geometry>
            <box size="0.01 0.01 0.01"/>
      </geometry>
    </collision>
  </link>
 
  <joint
    name="left_hip_socket"
    type="fixed">
    <origin
      xyz="0 0 0"
      rpy="0 0 0" />
    <parent
      link="left_upper_hip" />
    <child
      link="torso" />
    <axis
      xyz="0 0 0" />
  </joint>
  <link
    name="left_upper_shoulder">
    <inertial>
      <origin
        xyz="0.0271618501385941 0.0089955513332842 -3.0752386479399E-06"
        rpy="0 0 0" />
      <mass
        value="1.0322" />
      <inertia
        ixx="0.000376414409441782"
        ixy="1.74103175385179E-18"
        ixz="1.74000789530215E-18"
        iyy="0.000210235659214769"
        iyz="1.23791978619145E-20"
        izz="0.000210184181749588" />
    </inertial>
    <visual>
      <origin
        xyz="0 0 0"
        rpy="0 0 0" />
      <geometry>
        <mesh
          filename="meshes/left_upper_shoulder.STL" />
      </geometry>
      <material
        name="">
        <color
          rgba="0.792156862745098 0.819607843137255 0.933333333333333 1" />
      </material>
    </visual>
    <collision>
      <origin
        xyz="0 0 0"
        rpy="0 0 0" />
      <geometry>
        <mesh
          filename="hitboxes/left_upper_shoulder.STL" />
      </geometry>
    </collision>
  </link>
  <joint
    name="left_shoulder_socket"
    type="fixed">
    <origin
      xyz="-0.00646637584381726 -0.00399001273864397 0.365110348578025"
      rpy="1.23952297305487 0 0" />
    <parent
      link="torso" />
    <child
      link="left_upper_shoulder" />
    <axis
      xyz="0 0 0" />
  </joint>
  <link
    name="left_mid_shoulder">
    <inertial>
      <origin
        xyz="0.0634305669563471 0.000892300599833029 4.23257639452224E-06"
        rpy="0 0 0" />
      <mass
        value="0.75214" />
      <inertia
        ixx="0.000658004593033912"
        ixy="7.99737400888275E-06"
        ixz="2.18122406335215E-08"
        iyy="0.00107150303754144"
        iyz="-3.60957653437828E-10"
        izz="0.000766086781163016" />
    </inertial>
    <visual>
      <origin
        xyz="0 0 0"
        rpy="0 0 0" />
      <geometry>
        <mesh
          filename="meshes/left_mid_shoulder.STL" />
      </geometry>
      <material
        name="">
        <color
          rgba="0.792156862745098 0.819607843137255 0.933333333333333 1" />
      </material>
    </visual>
    <collision>
      <origin
        xyz="0 0 0"
        rpy="0 0 0" />
      <geometry>
        <mesh
          filename="hitboxes/left_mid_shoulder.STL" />
      </geometry>
    </collision>
  </link>
  <joint
    name="left_shoulder_roll"
    type="revolute">
    <origin
      xyz="0.066745 0.00899599999999999 0"
      rpy="0 0 0" />
    <parent
      link="left_upper_shoulder" />
    <child
      link="left_mid_shoulder" />
    <axis
      xyz="1 0 0" />
    <limit
      lower="-3.14"
      upper="3.14"
      effort="100"
      velocity="10" />
  </joint>
  <link
    name="left_lower_shoulder">
    <inertial>
      <origin
        xyz="0.0122569741762997 0.054438434768423 -0.00322636860512628"
        rpy="0 0 0" />
      <mass
        value="2.61637" />
      <inertia
        ixx="0.00092364552390218"
        ixy="-0.000113167686848102"
        ixz="2.23342586354056E-06"
        iyy="0.00101009132389113"
        iyz="1.35838401458036E-06"
        izz="0.00149831741851617" />
    </inertial>
    <visual>
      <origin
        xyz="0 0 0"
        rpy="0 0 0" />
      <geometry>
        <mesh
          filename="meshes/left_lower_shoulder.STL" />
      </geometry>
      <material
        name="">
        <color
          rgba="0.792156862745098 0.819607843137255 0.933333333333333 1" />
      </material>
    </visual>
    <collision>
      <origin
        xyz="0 0 0"
        rpy="0 0 0" />
      <geometry>
        <mesh
          filename="hitboxes/left_lower_shoulder.STL" />
      </geometry>
    </collision>
  </link>
  <joint
    name="left_shoulder_yaw"
    type="revolute">
    <origin
      xyz="0.067299 0.0554992 0"
      rpy="0 0 0" />
    <parent
      link="left_mid_shoulder" />
    <child
      link="left_lower_shoulder" />
    <axis
      xyz="0 1 0" />
    <limit
      lower="-3.14"
      upper="3.14"
      effort="100"
      velocity="10" />
  </joint>
  <link
    name="left_upper_arm">
    <inertial>
      <origin
        xyz="0.0680878276172435 -0.080803498532968 -0.0232359507760549"
        rpy="0 0 0" />
      <mass
        value="0.43865" />
      <inertia
        ixx="0.00210150716563964"
        ixy="0.000426798990964393"
        ixz="2.55939587534797E-05"
        iyy="0.000297607758878628"
        iyz="-5.27943576453916E-05"
        izz="0.00232628369223069" />
    </inertial>
    <visual>
      <origin
        xyz="0 0 0"
        rpy="0 0 0" />
      <geometry>
        <mesh
          filename="meshes/left_upper_arm.STL" />
      </geometry>
      <material
        name="">
        <color
          rgba="0.792156862745098 0.819607843137255 0.933333333333333 1" />
      </material>
    </visual>
    <collision>
      <origin
        xyz="0 0 0"
        rpy="0 0 0" />
      <geometry>
        <mesh
          filename="hitboxes/left_upper_arm.STL" />
      </geometry>
    </collision>
  </link>
  <joint
    name="left_shoulder_pitch"
    type="revolute">
    <origin
      xyz="0.0933702 0.0715308 0"
      rpy="0 0 0" />
    <parent
      link="left_lower_shoulder" />
    <child
      link="left_upper_arm" />
    <axis
      xyz="0 0 1" />
    <limit
      lower="-1.0"
      upper="1.0"
      effort="100"
      velocity="10" />
  </joint>
  <link
    name="left_lower_arm">
    <inertial>
      <origin
        xyz="-6.80380939057645E-05 -0.0924468362788842 0.00892003185905577"
        rpy="0 0 0" />
      <mass
        value="0.23097" />
      <inertia
        ixx="0.000511599728619131"
        ixy="1.48028869598552E-11"
        ixz="1.31845993829281E-11"
        iyy="4.8482326293528E-05"
        iyz="-3.97311903362346E-07"
        izz="0.000541631572358528" />
    </inertial>
    <visual>
      <origin
        xyz="0 0 0"
        rpy="0 0 0" />
      <geometry>
        <mesh
          filename="meshes/left_lower_arm.STL" />
      </geometry>
      <material
        name="">
        <color
          rgba="0.792156862745098 0.819607843137255 0.933333333333333 1" />
      </material>
    </visual>
    <collision>
      <origin
        xyz="0 0 0"
        rpy="0 0 0" />
      <geometry>
        <mesh
          filename="hitboxes/left_lower_arm.STL" />
      </geometry>
    </collision>
  </link>
  <joint
    name="left_elbow"
    type="revolute">
    <origin
      xyz="0.0848818 -0.233245 -0.000766900000000001"
      rpy="0 0 0" />
    <parent
      link="left_upper_arm" />
    <child
      link="left_lower_arm" />
    <axis
      xyz="0 0 1" />
    <limit
      lower="-1.57"
      upper="1.57"
      effort="100"
      velocity="10" />
  </joint>
  <link
    name="left_upper_wrist">
    <inertial>
      <origin
        xyz="-1.33226762955019E-15 0.00207186102276757 -5.55111512312578E-17"
        rpy="0 0 0" />
      <mass
        value="0.000181546469980574" />
      <inertia
        ixx="1.82947692151147E-09"
        ixy="1.39926517480375E-23"
        ixz="-2.16195505271555E-24"
        iyy="1.2561203010206E-09"
        iyz="1.74180487872799E-24"
        izz="1.82947692151147E-09" />
    </inertial>
    <visual>
      <origin
        xyz="0 0 0"
        rpy="0 0 0" />
      <geometry>
        <mesh
          filename="meshes/left_upper_wrist.STL" />
      </geometry>
      <material
        name="">
        <color
          rgba="0.792156862745098 0.819607843137255 0.933333333333333 1" />
      </material>
    </visual>
    <collision>
      <origin
        xyz="0 0 0"
        rpy="0 0 0" />
      <geometry>
        <mesh
          filename="hitboxes/left_upper_wrist.STL" />
      </geometry>
    </collision>
  </link>
  <joint
    name="left_wrist_1"
    type="revolute">
    <origin
      xyz="-6.80361886481462E-05 -0.183701 0.000766924761353371"
      rpy="0 0 0" />
    <parent
      link="left_lower_arm" />
    <child
      link="left_upper_wrist" />
    <axis
      xyz="0 0 1" />
    <limit
      lower="-1.57"
      upper="1.57"
      effort="100"
      velocity="10" />
  </joint>
  <link
    name="left_lower_wrist">
    <inertial>
      <origin
        xyz="-9.43689570931383E-16 -0.0288031389772324 0"
        rpy="0 0 0" />
      <mass
        value="0.14705" />
      <inertia
        ixx="5.50681999840716E-07"
        ixy="5.79026428787119E-21"
        ixz="1.4338335813297E-23"
        iyy="1.38038954105992E-08"
        iyz="8.15871502615777E-23"
        izz="5.58006732380988E-07" />
    </inertial>
    <visual>
      <origin
        xyz="0 0 0"
        rpy="0 0 0" />
      <geometry>
        <mesh
          filename="meshes/left_lower_wrist.STL" />
      </geometry>
      <material
        name="">
        <color
          rgba="0.792156862745098 0.819607843137255 0.933333333333333 1" />
      </material>
    </visual>
    <collision>
      <origin
        xyz="0 0 0"
        rpy="0 0 0" />
      <geometry>
        <mesh
          filename="hitboxes/left_lower_wrist.STL" />
      </geometry>
    </collision>
  </link>
  <joint
    name="left_wrist_2"
    type="revolute">
    <origin
      xyz="0 0 0"
      rpy="0 0 0" />
    <parent
      link="left_upper_wrist" />
    <child
      link="left_lower_wrist" />
    <axis
      xyz="-1 0 0" />
    <limit
      lower="-1.57"
      upper="1.57"
      effort="100"
      velocity="10" />
  </joint>
  <link
    name="left_hand">
    <inertial>
      <origin
        xyz="-5.88418203051333E-15 -0.00200000000000322 4.85722573273506E-17"
        rpy="0 0 0" />
      <mass
        value="0.000181546469980576" />
      <inertia
        ixx="1.82947692151149E-09"
        ixy="-2.02430346168117E-41"
        ixz="5.11791892852002E-26"
        iyy="1.25612030102061E-09"
        iyz="8.83524213847533E-26"
        izz="1.82947692151149E-09" />
    </inertial>
    <visual>
      <origin
        xyz="0 0 0"
        rpy="0 0 0" />
      <geometry>
        <mesh
          filename="meshes/left_hand.STL" />
      </geometry>
      <material
        name="">
        <color
          rgba="0.792156862745098 0.819607843137255 0.933333333333333 1" />
      </material>
    </visual>
    <collision>
      <origin
        xyz="0 0 0"
        rpy="0 0 0" />
      <geometry>
        <mesh
          filename="hitboxes/left_hand.STL" />
      </geometry>
    </collision>
  </link>
  <joint
    name="left_palm"
    type="fixed">
    <origin
      xyz="0 -0.0576781389772325 0"
      rpy="0 0 0" />
    <parent
      link="left_lower_wrist" />
    <child
      link="left_hand" />
    <axis
      xyz="0 0 0" />
  </joint>
  <link
    name="right_upper_shoulder">
    <inertial>
      <origin
        xyz="-0.0271618501385927 0.00899555133328418 3.07523864775255E-06"
        rpy="0 0 0" />
      <mass
        value="1.0322" />
      <inertia
        ixx="0.000376414409441782"
        ixy="-1.73201177564963E-18"
        ixz="2.9050211600979E-18"
        iyy="0.000210235659214769"
        iyz="-2.16297085930886E-20"
        izz="0.000210184181749588" />
    </inertial>
    <visual>
      <origin
        xyz="0 0 0"
        rpy="0 0 0" />
      <geometry>
        <mesh
          filename="meshes/right_upper_shoulder.STL" />
      </geometry>
      <material
        name="">
        <color
          rgba="0.792156862745098 0.819607843137255 0.933333333333333 1" />
      </material>
    </visual>
    <collision>
      <origin
        xyz="0 0 0"
        rpy="0 0 0" />
      <geometry>
        <mesh
          filename="hitboxes/right_upper_shoulder.STL" />
      </geometry>
    </collision>
  </link>
  <joint
    name="right_shoulder_socket"
    type="fixed">
    <origin
      xyz="-0.0229578687628436 -0.00398386249554276 0.365110402250384"
      rpy="1.23952297305487 0 0" />
    <parent
      link="torso" />
    <child
      link="right_upper_shoulder" />
    <axis
      xyz="0 0 0" />
  </joint>
  <link
    name="right_mid_shoulder">
    <inertial>
      <origin
        xyz="-0.0634305669563456 0.000892300599832987 -4.2325763949802E-06"
        rpy="0 0 0" />
      <mass
        value="0.75214"/>
      <inertia
        ixx="0.000658004593033911"
        ixy="-7.99737400888272E-06"
        ixz="2.18122406326681E-08"
        iyy="0.00107150303754144"
        iyz="3.60957653374029E-10"
        izz="0.000766086781163017" />
    </inertial>
    <visual>
      <origin
        xyz="0 0 0"
        rpy="0 0 0" />
      <geometry>
        <mesh
          filename="meshes/right_mid_shoulder.STL" />
      </geometry>
      <material
        name="">
        <color
          rgba="0.792156862745098 0.819607843137255 0.933333333333333 1" />
      </material>
    </visual>
    <collision>
      <origin
        xyz="0 0 0"
        rpy="0 0 0" />
      <geometry>
        <mesh
          filename="hitboxes/right_mid_shoulder.STL" />
      </geometry>
    </collision>
  </link>
  <joint
    name="right_shoulder_roll"
    type="revolute">
    <origin
      xyz="-0.066745 0.00899599999999999 0"
      rpy="0 0 0" />
    <parent
      link="right_upper_shoulder" />
    <child
      link="right_mid_shoulder" />
    <axis
      xyz="-1 0 0" />
    <limit
      lower="-3.14"
      upper="3.14"
      effort="100"
      velocity="10" />
  </joint>
  <link
    name="right_lower_shoulder">
    <inertial>
      <origin
        xyz="-0.0122569741762984 0.054438434768423 0.00322636860512623"
        rpy="0 0 0" />
      <mass
        value="2.61637" />
      <inertia
        ixx="0.00092364552390218"
        ixy="0.000113167686848102"
        ixz="2.23342586353657E-06"
        iyy="0.00101009132389113"
        iyz="-1.35838401457953E-06"
        izz="0.00149831741851617" />
    </inertial>
    <visual>
      <origin
        xyz="0 0 0"
        rpy="0 0 0" />
      <geometry>
        <mesh
          filename="meshes/right_lower_shoulder.STL" />
      </geometry>
      <material
        name="">
        <color
          rgba="0.792156862745098 0.819607843137255 0.933333333333333 1" />
      </material>
    </visual>
    <collision>
      <origin
        xyz="0 0 0"
        rpy="0 0 0" />
      <geometry>
        <mesh
          filename="hitboxes/right_lower_shoulder.STL" />
      </geometry>
    </collision>
  </link>
  <joint
    name="right_shoulder_yaw"
    type="revolute">
    <origin
      xyz="-0.067299 0.0554992 0"
      rpy="0 0 0" />
    <parent
      link="right_mid_shoulder" />
    <child
      link="right_lower_shoulder" />
    <axis
      xyz="0 1 0" />
    <limit
      lower="-3.14"
      upper="3.14"
      effort="100"
      velocity="10" />
  </joint>
  <link
    name="right_upper_arm">
    <inertial>
      <origin
        xyz="-0.0680878276172424 -0.0808034985329677 0.0232359507760542"
        rpy="0 0 0" />
      <mass
        value="0.43865" />
      <inertia
        ixx="0.00210150716563964"
        ixy="-0.000426798990964374"
        ixz="2.55939587534792E-05"
        iyy="0.000297607758878619"
        iyz="5.27943576453924E-05"
        izz="0.00232628369223069" />
    </inertial>
    <visual>
      <origin
        xyz="0 0 0"
        rpy="0 0 0" />
      <geometry>
        <mesh
          filename="meshes/right_upper_arm.STL" />
      </geometry>
      <material
        name="">
        <color
          rgba="0.792156862745098 0.819607843137255 0.933333333333333 1" />
      </material>
    </visual>
    <collision>
      <origin
        xyz="0 0 0"
        rpy="0 0 0" />
      <geometry>
        <mesh
          filename="hitboxes/right_upper_arm.STL" />
      </geometry>
    </collision>
  </link>
  <joint
    name="right_shoulder_pitch"
    type="revolute">
    <origin
      xyz="-0.0933702 0.0715308 0"
      rpy="0 0 0" />
    <parent
      link="right_lower_shoulder" />
    <child
      link="right_upper_arm" />
    <axis
      xyz="0 0 -1" />
    <limit
      lower="-1.0"
      upper="1.0"
      effort="100"
      velocity="10" />
  </joint>
  <link
    name="right_lower_arm">
    <inertial>
      <origin
        xyz="6.80380939069858E-05 -0.0924468362788842 -0.00892003185905575"
        rpy="0 0 0" />
      <mass
        value="0.23097" />
      <inertia
        ixx="0.000511599728619132"
        ixy="-1.48028820240139E-11"
        ixz="1.31845994066932E-11"
        iyy="4.84823262935281E-05"
        iyz="3.9731190336251E-07"
        izz="0.000541631572358529" />
    </inertial>
    <visual>
      <origin
        xyz="0 0 0"
        rpy="0 0 0" />
      <geometry>
        <mesh
          filename="meshes/right_lower_arm.STL" />
      </geometry>
      <material
        name="">
        <color
          rgba="0.792156862745098 0.819607843137255 0.933333333333333 1" />
      </material>
    </visual>
    <collision>
      <origin
        xyz="0 0 0"
        rpy="0 0 0" />
      <geometry>
        <mesh
          filename="hitboxes/right_lower_arm.STL" />
      </geometry>
    </collision>
  </link>
  <joint
    name="right_elbow"
    type="revolute">
    <origin
      xyz="-0.0848818 -0.233245 0.000766899999999404"
      rpy="0 0 0" />
    <parent
      link="right_upper_arm" />
    <child
      link="right_lower_arm" />
    <axis
      xyz="0 0 -1" />
    <limit
      lower="-1.57"
      upper="1.57"
      effort="100"
      velocity="10" />
  </joint>
  <link
    name="right_upper_wrist">
    <inertial>
      <origin
        xyz="2.38697950294409E-15 2.77555756156289E-17 -6.93889390390723E-18"
        rpy="0 0 0" />
      <mass
        value="0.000181546469980574" />
      <inertia
        ixx="1.82947692151148E-09"
        ixy="-8.21908173786814E-24"
        ixz="1.17094758190947E-24"
        iyy="1.25612030102059E-09"
        iyz="5.06636601554152E-25"
        izz="1.82947692151147E-09" />
    </inertial>
    <visual>
      <origin
        xyz="0 0 0"
        rpy="0 0 0" />
      <geometry>
        <mesh
          filename="meshes/right_upper_wrist.STL" />
      </geometry>
      <material
        name="">
        <color
          rgba="0.792156862745098 0.819607843137255 0.933333333333333 1" />
      </material>
    </visual>
    <collision>
      <origin
        xyz="0 0 0"
        rpy="0 0 0" />
      <geometry>
        <mesh
          filename="hitboxes/right_upper_wrist.STL" />
      </geometry>
    </collision>
  </link>
  <joint
    name="right_wrist_1"
    type="revolute">
    <origin
      xyz="6.80361886485348E-05 -0.181629138977232 -0.00076692476135333"
      rpy="0 0 0" />
    <parent
      link="right_lower_arm" />
    <child
      link="right_upper_wrist" />
    <axis
      xyz="0 0 -1" />
    <limit
      lower="-1.57"
      upper="1.57"
      effort="100"
      velocity="10" />
  </joint>
  <link
    name="right_lower_wrist">
    <inertial>
      <origin
        xyz="2.33146835171283E-15 -0.0288031389772324 6.93889390390723E-18"
        rpy="0 0 0" />
      <mass
        value="0.14705" />
      <inertia
        ixx="5.50681999840714E-07"
        ixy="-5.50107419090441E-21"
        ixz="-5.05375850320789E-23"
        iyy="1.38038954105991E-08"
        iyz="3.11000523274332E-23"
        izz="5.58006732380987E-07" />
    </inertial>
    <visual>
      <origin
        xyz="0 0 0"
        rpy="0 0 0" />
      <geometry>
        <mesh
          filename="meshes/right_lower_wrist.STL" />
      </geometry>
      <material
        name="">
        <color
          rgba="0.792156862745098 0.819607843137255 0.933333333333333 1" />
      </material>
    </visual>
    <collision>
      <origin
        xyz="0 0 0"
        rpy="0 0 0" />
      <geometry>
        <mesh
          filename="hitboxes/right_lower_wrist.STL" />
      </geometry>
    </collision>
  </link>
  <joint
    name="right_wrist_2"
    type="revolute">
    <origin
      xyz="0 -0.00207186102276752 0"
      rpy="0 0 0" />
    <parent
      link="right_upper_wrist" />
    <child
      link="right_lower_wrist" />
    <axis
      xyz="1 0 0" />
    <limit
      lower="-1.57"
      upper="1.57"
      effort="100"
      velocity="10" />
  </joint>
  <link
    name="right_hand">
    <inertial>
      <origin
        xyz="5.88418203051333E-15 -0.00200000000000322 -4.85722573273506E-17"
        rpy="0 0 0" />
      <mass
        value="0.000181546469980575" />
      <inertia
        ixx="1.82947692151148E-09"
        ixy="-4.48072994165536E-24"
        ixz="-3.50117862703736E-24"
        iyy="1.25612030102061E-09"
        iyz="4.75453556918445E-26"
        izz="1.82947692151148E-09" />
    </inertial>
    <visual>
      <origin
        xyz="0 0 0"
        rpy="0 0 0" />
      <geometry>
        <mesh
          filename="meshes/right_hand.STL" />
      </geometry>
      <material
        name="">
        <color
          rgba="0.792156862745098 0.819607843137255 0.933333333333333 1" />
      </material>
    </visual>
    <collision>
      <origin
        xyz="0 0 0"
        rpy="0 0 0" />
      <geometry>
        <mesh
          filename="hitboxes/right_hand.STL" />
      </geometry>
    </collision>
  </link>
  <joint
    name="right_palm"
    type="fixed">
    <origin
      xyz="0 -0.0576781389772325 0"
      rpy="0 0 0" />
    <parent
      link="right_lower_wrist" />
    <child
      link="right_hand" />
    <axis
      xyz="0 0 0" />
  </joint>
  <link
    name="right_upper_hip">
    <inertial>
      <origin
        xyz="0.0205119008037698 -4.33683071792562E-05 6.5323732733602E-05"
        rpy="0 0 0" />
      <mass
        value="0.814" />
      <inertia
        ixx="0.000271725667498223"
        ixy="-2.03555206724895E-07"
        ixz="3.06989269423616E-07"
        iyy="0.000173074203349512"
        iyz="-7.39650613074923E-10"
        izz="0.000173712876550449" />
    </inertial>
    <visual>
      <origin
        xyz="0 0 0"
        rpy="0 0 0" />
      <geometry>
        <mesh
          filename="meshes/right_upper_hip.STL" />
      </geometry>
      <material
        name="">
        <color
          rgba="0.792156862745098 0.819607843137255 0.933333333333333 1" />
      </material>
    </visual>
    <collision>
      <origin
        xyz="0 0 0"
        rpy="0 0 0" />
      <geometry>
        <mesh
          filename="hitboxes/right_upper_hip.STL" />
      </geometry>
    </collision>
  </link>
  <joint
    name="right_hip_socket"
    type="fixed">
    <origin
      xyz="-0.0277214108608382 0 0"
      rpy="3.14159265358979 0 3.14159265358979" />
    <parent
      link="torso" />
    <child
      link="right_upper_hip" />
    <axis
      xyz="0 0 0" />
  </joint>
  <link
    name="right_mid_hip">
    <inertial>
      <origin
        xyz="0.121598846761327 0.0372219754056857 -0.00316773141225046"
        rpy="0 0 0" />
      <mass
        value="1.344" />
      <inertia
        ixx="0.00108085399340604"
        ixy="-7.2719360112188E-06"
        ixz="7.41325110057048E-06"
        iyy="0.0012304329254962"
        iyz="0.000115540657687724"
        izz="0.00179005521215836" />
    </inertial>
    <visual>
      <origin
        xyz="0 0 0"
        rpy="0 0 0" />
      <geometry>
        <mesh
          filename="meshes/right_mid_hip.STL" />
      </geometry>
      <material
        name="">
        <color
          rgba="0.792156862745098 0.819607843137255 0.933333333333333 1" />
      </material>
    </visual>
    <collision>
      <origin
        xyz="0 0 0"
        rpy="0 0 0" />
      <geometry>
        <mesh
          filename="hitboxes/right_mid_hip.STL" />
      </geometry>
    </collision>
  </link>
  <joint
    name="right_hip_roll"
    type="revolute">
    <origin
      xyz="0 0 0"
      rpy="0 0 0" />
    <parent
      link="right_upper_hip" />
    <child
      link="right_mid_hip" />
    <axis
      xyz="1 0 0" />
    <limit
      lower="-0.523599"
      upper="2.0944"
      effort="100"
      velocity="10" />
  </joint>
  <link
    name="right_lower_hip">
    <inertial>
      <origin
        xyz="-4.240577047121E-06 0.00466041098683934 0.0570690443463173"
        rpy="0 0 0" />
      <mass
        value="1.787" />
      <inertia
        ixx="0.00156617282758852"
        ixy="1.05074128404359E-09"
        ixz="1.1565126971142E-09"
        iyy="0.00324302275063911"
        iyz="5.53836163707539E-06"
        izz="0.00370473867635984" />
    </inertial>
    <visual>
      <origin
        xyz="0 0 0"
        rpy="0 0 0" />
      <geometry>
        <mesh
          filename="meshes/right_lower_hip.STL" />
      </geometry>
      <material
        name="">
        <color
          rgba="0.792156862745098 0.819607843137255 0.933333333333333 1" />
      </material>
    </visual>
    <collision>
      <origin
        xyz="0 0 0"
        rpy="0 0 0" />
      <geometry>
        <mesh
          filename="hitboxes/right_lower_hip.STL" />
      </geometry>
    </collision>
  </link>
  <joint
    name="right_hip_yaw"
    type="revolute">
    <origin
      xyz="0.123604 -0.0044744107935495 0.00203512359589475"
      rpy="0 0 0" />
    <parent
      link="right_mid_hip" />
    <child
      link="right_lower_hip" />
    <axis
      xyz="0 1 0" />
    <limit
      lower="-0.523599"
      upper="1.57"
      effort="100"
      velocity="10" />
  </joint>
  <link
    name="right_upper_leg">
    <inertial>
      <origin
        xyz="-9.40589058531782E-06 -7.49586306215272E-06 0.131327434758344"
        rpy="0 0 0" />
      <mass
        value="3.189" />
      <inertia
        ixx="0.0148991129479231"
        ixy="-4.0108204173741E-07"
        ixz="-3.07015042382686E-07"
        iyy="0.0126395461409201"
        iyz="-2.036550032069E-07"
        izz="0.00357733051851497" />
    </inertial>
    <visual>
      <origin
        xyz="0 0 0"
        rpy="0 0 0" />
      <geometry>
        <mesh
          filename="meshes/right_upper_leg.STL" />
      </geometry>
      <material
        name="">
        <color
          rgba="0.792156862745098 0.819607843137255 0.933333333333333 1" />
      </material>
    </visual>
    <collision>
      <origin
        xyz="0 0 0"
        rpy="0 0 0" />
      <geometry>
        <mesh
          filename="hitboxes/right_upper_leg.STL" />
      </geometry>
    </collision>
  </link>
  <joint
    name="right_hip_pitch"
    type="revolute">
    <origin
      xyz="0 0.00447717290602087 0.0499628322232597"
      rpy="0 0 0" />
    <parent
      link="right_lower_hip" />
    <child
      link="right_upper_leg" />
    <axis
      xyz="0 0 -1" />
    <limit
      lower="-0.523599"
      upper="1.57"
      effort="100"
      velocity="10" />
  </joint>
  <link
    name="right_lower_leg">
    <inertial>
      <origin
        xyz="0.00165417081533123 -1.87078091120479E-06 0.093873682688678"
        rpy="0 0 0" />
      <mass
        value="1.117" />
      <inertia
        ixx="0.00515989275577795"
        ixy="-1.89701287739222E-07"
        ixz="-4.12271687322285E-17"
        iyy="0.0045501762301449"
        iyz="-6.01254329222372E-13"
        izz="0.000833155112619076" />
    </inertial>
    <visual>
      <origin
        xyz="0 0 0"
        rpy="0 0 0" />
      <geometry>
        <mesh
          filename="meshes/right_lower_leg.STL" />
      </geometry>
      <material
        name="">
        <color
          rgba="0.792156862745098 0.819607843137255 0.933333333333333 1" />
      </material>
    </visual>
    <collision>
      <origin
        xyz="0 0 0"
        rpy="0 0 0" />
      <geometry>
        <mesh
          filename="hitboxes/right_lower_leg.STL" />
      </geometry>
    </collision>
  </link>
  <joint
    name="right_knee"
    type="revolute">
    <origin
      xyz="0 0.00360621292742507 0.320410730513699"
      rpy="0 0 0" />
    <parent
      link="right_upper_leg" />
    <child
      link="right_lower_leg" />
    <axis
      xyz="-1 0 0" />
    <limit
      lower="0"
      upper="1.57"
      effort="100"
      velocity="10" />
  </joint>
  <link
    name="right_ankle">
    <inertial>
      <origin
        xyz="0.00163394837517195 -2.31851315721926E-06 0.0137143461586106"
        rpy="0 0 0" />
      <mass
        value="0.1" />
      <inertia
        ixx="3.8768287485402E-05"
        ixy="-1.97400765665865E-11"
        ixz="1.05909526353183E-12"
        iyy="4.42522549922276E-05"
        iyz="-4.39665630252677E-12"
        izz="5.95308829970064E-05" />
    </inertial>
    <visual>
      <origin
        xyz="0 0 0"
        rpy="0 0 0" />
      <geometry>
        <mesh
          filename="meshes/right_ankle.STL" />
      </geometry>
      <material
        name="">
        <color
          rgba="0.792156862745098 0.819607843137255 0.933333333333333 1" />
      </material>
    </visual>
    <collision>
      <origin
        xyz="0 0 0"
        rpy="0 0 0" />
      <geometry>
        <mesh
          filename="hitboxes/right_ankle.STL" />
      </geometry>
    </collision>
  </link>
  <joint
    name="right_ankle-1"
    type="revolute">
    <origin
      xyz="0 0 0.224765554678246"
      rpy="0 0 0" />
    <parent
      link="right_lower_leg" />
    <child
      link="right_ankle" />
    <axis
      xyz="-1 0 0" />
    <limit
      lower="-0.523599"
      upper="0.523599"
      effort="100"
      velocity="10" />
  </joint>
  <link
    name="right_foot">
    <inertial>
      <origin
        xyz="-0.00133749415390572 -0.0723411944092442 0.0359096065872807"
        rpy="0 0 0" />
      <mass
        value="1.139" />
      <inertia
        ixx="0.00297492439137068"
        ixy="-4.09688209100065E-05"
        ixz="-1.67377251040505E-05"
        iyy="0.000478682103839178"
        iyz="0.000147310307159496"
        izz="0.00314575025031375" />
    </inertial>
    <visual>
      <origin
        xyz="0 0 0"
        rpy="0 3.14 0" />
      <geometry>
        <mesh
          filename="meshes/left_foot.STL" />
      </geometry>
      <material
        name="">
        <color
          rgba="0.792156862745098 0.819607843137255 0.933333333333333 1" />
      </material>
    </visual>
    <collision>
      <origin
        xyz="0 0 0"
        rpy="0 0 0" />
      <geometry>
        <mesh
          filename="hitboxes/right_foot.STL" />
      </geometry>
    </collision>
  </link>
  <joint
    name="right_ankle-2"
    type="revolute">
    <origin
      xyz="0.001638 0.00019896500936286 0.022799131845863"
      rpy="0 0 0" />
    <parent
      link="right_ankle" />
    <child
      link="right_foot" />
    <axis
      xyz="0 1 0" />
    <limit
      lower="-1.0"
      upper="1.0"
      effort="100"
      velocity="10" />
  </joint>
  
   <joint
    name="torso_centre_joint"
    type="revolute">
    <origin
      xyz="0 0 0"
      rpy="0 0 0" />
    <parent
      link="torso" />
    <child
      link="torso_centre" />
    <axis
      xyz="1 0 0" />
    <limit
      lower="-0.01"
      upper="0.01"
      effort="0.01"
      velocity="0.01" />
  </joint>
 
</robot>
